Workbook

Sheet 5G물자
A1: 대분류 | B1: 중분류 | C1: 소분류 | D1: 자재코드 | E1: 품명 | F1: 제조사 | G1: 이월_신품 | H1: 이월_구품 | I1: 이월(재고) | J1: 신품 | K1: 구품 | L1: 재고 | M1: 전체
A2: 5G | B2: DUL | C2: AAU10 | D2: 1000063437 | E2: =VLOOKUP(D2,[1]자재마스터!$A:$C,3,0) -> AAU10-3.5G-32T,삼성전자,5G RAN | F2: 삼성전자
A3: 5G | B3: DUL | C3: AAU20 | D3: 1000064890 | E3: =VLOOKUP(D3,[1]자재마스터!$A:$C,3,0) -> AAU20-3.5G-32T,삼성전자,5G RAN | F3: 삼성전자
A4: 5G | B4: DUL | C4: AAU21 | D4: 1000066569 | E4: =VLOOKUP(D4,[1]자재마스터!$A:$C,3,0) -> AAU21-3.5G-32T,삼성전자,5G RAN | F4: 삼성전자
A5: 5G | B5: DUL | C5: AAU20 | D5: 1000067082 | E5: AAU20-3.5G-64T | F5: 삼성전자
A6: 5G | B6: DUL | C6: DAU10 | D6: 1000065297 | E6: =VLOOKUP(D6,[1]자재마스터!$A:$C,3,0) -> DAU10-28G-1024T(SS),삼성전자,5G RAN | F6: 삼성전자
A7: 5G | B7: DUH | C7: DUH10(내) | D7: 1000063406 | E7: =VLOOKUP(D7,[1]자재마스터!$A:$C,3,0) -> DUH-Shelf10,삼성전자,5G RAN | F7: 삼성전자
A8: 5G | B8: DUH | C8: DUH10(내) | D8: 1000063435 | E8: =VLOOKUP(D8,[1]자재마스터!$A:$C,3,0) -> DUH-MP10,삼성전자,5G RAN | F8: 삼성전자
A9: 5G | B9: DUH | C9: DUH10(내) | D9: 1000063436 | E9: =VLOOKUP(D9,[1]자재마스터!$A:$C,3,0) -> DUH-CC10,삼성전자,5G RAN | F9: 삼성전자
A10: 5G | B10: DUH | C10: DUH20(내) | D10: 1000064885 | E10: =VLOOKUP(D10,[1]자재마스터!$A:$C,3,0) -> DUH-Shelf20,삼성전자,5G RAN | F10: 삼성전자
A11: 5G | B11: DUH | C11: DUH20(내) | D11: 1000064886 | E11: =VLOOKUP(D11,[1]자재마스터!$A:$C,3,0) -> DUH-MP20,삼성전자,5G RAN | F11: 삼성전자
A12: 5G | B12: DUH | C12: DUH20(내) | D12: 1000064888 | E12: =VLOOKUP(D12,[1]자재마스터!$A:$C,3,0) -> DUH-CC20,삼성전자,5G RAN | F12: 삼성전자
A13: 5G | B13: DUH | C13: DUH20(외) | D13: 1000064887 | E13: =VLOOKUP(D13,[1]자재마스터!$A:$C,3,0) -> DUH-MP20(외),삼성전자,5G RAN | F13: 삼성전자
A14: 5G | B14: DUH | C14: DUH20(외) | D14: 1000064889 | E14: =VLOOKUP(D14,[1]자재마스터!$A:$C,3,0) -> DUH-CC20(외),삼성전자,5G RAN | F14: 삼성전자
A15: 5G | B15: DUH | C15: DUH20(외) | D15: 1000065169 | E15: =VLOOKUP(D15,[1]자재마스터!$A:$C,3,0) -> DUH-Cabinet(외),삼성전자,5G RAN | F15: 삼성전자
A16: 5G | B16: DUH | C16: DUH20(외) | D16: 1000065170 | E16: =VLOOKUP(D16,[1]자재마스터!$A:$C,3,0) -> DUH-설치자재(외),삼성전자,5G RAN | F16: 삼성전자
A17: 5G | B17: PRU | C17: PRU-3.5G-8T | D17: 1000064248 | E17: =VLOOKUP(D17,[1]자재마스터!$A:$C,3,0) -> PRU10-3.5G-8T,삼성전자,5G RAN | F17: 삼성전자
A18: 5G | B18: PRU | C18: PRU-3.5G-8T | D18: 1000067036 | E18: PRU11-3.5G-8T | F18: 삼성전자
A19: 5G | B19: PRU | C19: RO-PRU-3.5G-4T | D19: 1000064902 | E19: =VLOOKUP(D19,[1]자재마스터!$A:$C,3,0) -> PRU-3.5G-4T/SKTS,SKTS,PRU-3.5G-4T/SKTS | F19: SKTS
A20: 5G | B20: PRU | C20: RO-PRU-3.5G-4T | D20: 1000064758 | E20: =VLOOKUP(D20,[1]자재마스터!$A:$C,3,0) -> PRU-3.5G-4T/ANTS,에이앤티에스,PRU-3.5G-4T/ANTS | F20: ANTS
A21: 5G | B21: PRU | C21: RO-PRU-3.5G-2T | D21: 1000064759 | E21: PRU-3.5G-2T/ANTS,에이앤티에스,PRU-3.5G-2T/ANTS | F21: ANTS
A22: 5G | B22: PRU | C22: RO-PRU-3.5G-2T | D22: 1000064903 | E22: PRU-3.5G-2T/SKTS,SKTS,PRU-3.5G-2T/SKTS | F22: SKTS
A23: 5G | B23: LSH | C23: LS-3.5G | D23: 1000064695 | E23: =VLOOKUP(D23,[1]자재마스터!$A:$C,3,0) -> LS-3.5G-100M,삼성전자,5G | F23: 삼성전자
A24: 5G | B24: 5G 정류기 | C24: Compact 정류기_소 | D24: 1000063300 | E24: =VLOOKUP(D24,[1]자재마스터!$A:$C,3,0) -> 5G 정류기,Compact 48V_1.2kW용 | F24: 행복나래
A25: 5G | B25: 5G 정류기 | C25: Compact 정류기_대 | D25: 1000063371 | E25: =VLOOKUP(D25,[1]자재마스터!$A:$C,3,0) -> 5G 정류기,Compact 48V_2.0kW용 | F25: 행복나래
A26: 5G | B26: 5G 정류기 | C26: Compact 정류기_소 | D26: 1000065250 | E26: =VLOOKUP(D26,[1]자재마스터!$A:$C,3,0) -> 5G 정류기,Compact 48V_1.5kW용 | F26: 행복나래
A27: 5G | B27: 5G 정류기 | C27: Compact 정류기_대 | D27: 1000065296 | E27: =VLOOKUP(D27,[1]자재마스터!$A:$C,3,0) -> 5G 정류기,Compact 48V_2.3kW용 | F27: 행복나래
A28: 5G | B28: 5G 정류기 | C28: 브라켓_소 | D28: 1000065731 | E28: =VLOOKUP(D28,[1]자재마스터!$A:$C,3,0) -> 5G정류기Compact 48C 1.5KW브라켓(개별형) , | F28: 행복나래
A29: 5G | B29: 5G 정류기 | C29: 브라켓_대 | D29: 1000065732 | E29: =VLOOKUP(D29,[1]자재마스터!$A:$C,3,0) -> 5G정류기Compact 48C 2.3kW브라켓(개별형), | F29: 행복나래
A30: 5G | B30: 5G 정류기 | C30: 브라켓_소 | D30: 1000063337 | E30: =VLOOKUP(D30,[1]자재마스터!$A:$C,3,0) -> 5G 정류기,Compact 48C_1.2kW 브라켓(개별형) | F30: 행복나래
A31: 5G | B31: 5G 정류기 | C31: 브라켓_대 | D31: 1000063369 | E31: =VLOOKUP(D31,[1]자재마스터!$A:$C,3,0) -> 5G 정류기,Compact 48C_2.0kW 브라켓(개별형) | F31: 행복나래
A32: 5G | B32: 5G 정류기 | C32: 브라켓_공 | D32: 1000063370 | E32: =VLOOKUP(D32,[1]자재마스터!$A:$C,3,0) -> 5G 정류기,Compact 48C_공용브라켓(적층형) | F32: 행복나래
A33: 5G | B33: Bypass | C33: SMUX-Bypass | D33: 1000064457 | E33: =VLOOKUP(D33,[1]자재마스터!$A:$C,3,0) -> SMUX-Bypass,5G-PON | F33: 썬웨이브
A34: 5G | B34: S-MUX | C34: SMUX-C | D34: 1000064447 | E34: =VLOOKUP(D34,[1]자재마스터!$A:$C,3,0) -> SMUX-C_New,SMUX COT 1290nm(필터형) | F34: 썬웨이브
... A52: 5G | B52: L-MUX | C52: LMUX-R | D52: 1000065543 | E52: =VLOOKUP(D52,[1]자재마스터!$A:$C,3,0) -> LMUX-R,코위버(주),UTRANS-4200L | F52: 코위버
A53: 5G | B53: L-MUX | C53: LMUX-C | D53: 1000066556 | E53: LMUX-C,쏠리드,5G-MUX | F53: 쏠리드
A54: 5G | B54: L-MUX | C54: LMUX-R | D54: 1000066555 | E54: LMUX-R,쏠리드,5G-MUX | F54: 쏠리드
A55: 5G | B55: L-MUX | C55: LMUX-C | D55: 1000065061 | E55: =VLOOKUP(D55,[1]자재마스터!$A:$C,3,0) -> LMUX-C,COT | F55: 인텍이앤씨
A56: 5G | B56: L-MUX | C56: LMUX-R | D56: 1000065062 | E56: =VLOOKUP(D56,[1]자재마스터!$A:$C,3,0) -> LMUX-R,RN | F56: 인텍이앤씨
A57: 5G | B57: L-MUX | C57: LMUX-C | D57: 1000066598 | E57: LMUX-C,(주)인텍이앤씨,LMUX-COT | F57: 인텍이앤씨
...

Sheet 5G,LTE물자
A1: 대분류 | B1: 소분류 | C1: 자재코드 | D1: 품명 | E1: 제조사 | F1: 이월_신품 | G1: 이월_구품 | H1: 이월(재고) | I1: 신품 | J1: 구품 | K1: 재고 | L1: 전체
A2: 5G | B2: AAU10(SS) | C2: 1000063437 | D2: =VLOOKUP(C2,[1]자재마스터!$A:$C,3,0) -> AAU10-3.5G-32T,삼성전자,5G RAN | E2: 삼성전자
A3: 5G | B3: AAU20(SS) | C3: 1000064890 | D3: =VLOOKUP(C3,[1]자재마스터!$A:$C,3,0) -> AAU20-3.5G-32T,삼성전자,5G RAN | E3: 삼성전자
A4: 5G | B4: AAU20(ELG) | C4: 1000065566 | D4: =VLOOKUP(C4,[1]자재마스터!$A:$C,3,0) -> AAU20-3.5G-32T,ERICSSON-LG,AIR3227 | E4: ELG
A5: 5G | B5: AAU21(SS) | C5: 1000066569 | D5: =VLOOKUP(C5,[1]자재마스터!$A:$C,3,0) -> AAU21-3.5G-32T,삼성전자,5G RAN | E5: 삼성전자
A6: 5G | B6: PRU-3.5G-8T | C6: 1000064248 | D6: =VLOOKUP(C6,[1]자재마스터!$A:$C,3,0) -> PRU10-3.5G-8T,삼성전자,5G RAN | E6: 삼성전자
A7: 5G | B7: PRU10-3.5G-4T(EL) | C7: 1000064675 | D7: =VLOOKUP(C7,[1]자재마스터!$A:$C,3,0) -> PRU10-3.5G-4T,ERICSSON-LG,Radio4422 B78C | E7: ELG
A8: 5G | B8: PRU10-3.5G-8T(NSN) | C8: 1000064650 | D8: =VLOOKUP(C8,[1]자재마스터!$A:$C,3,0) -> PRU10-3.5G-8T,NSN,NSN/AZQL(3.5GHz)/8TRX | E8: NSS
A9: 5G | B9: RO-PRU-3.5G-4T(SKTS) | C9: 1000064902 | D9: =VLOOKUP(C9,[1]자재마스터!$A:$C,3,0) -> PRU-3.5G-4T/SKTS,SKTS,PRU-3.5G-4T/SKTS | E9: SKTS
A10: 5G | B10: RO-PRU-3.5G-4T(ANTS) | C10: 1000064758 | D10: =VLOOKUP(C10,[1]자재마스터!$A:$C,3,0) -> PRU-3.5G-4T/ANTS,에이앤티에스,PRU-3.5G-4T/ANTS | E10: ANTS
A11: LTE DBRRU | B11: DBRRU 2.1G/1.8G | C11: 1000065286 | D11: =VLOOKUP(C11,[1]자재마스터!$A:$C,3,0) -> Dualband RU(2.1G/1.8G),삼성전자,LTE RAN | E11: 삼성전자
A12: LTE RRU | B12: RRU 1.8G(10W) | C12: 1000056038 | D12: =VLOOKUP(C12,[1]자재마스터!$A:$C,3,0) -> CRU 본체,1.8GHz,삼성전자,LTE eNB | E12: 삼성전자
A13: LTE RRU | B13: RRU 1.8G | C13: 1000051223 | D13: =VLOOKUP(C13,[1]자재마스터!$A:$C,3,0) -> RRU(종단형),1.8GHz,삼성전자,LTE eNB | E13: 삼성전자
... A20: LTE RRU | B20: RRU 2.6G | C20: 1000059604 | D20: =VLOOKUP(C20,[1]자재마스터!$A:$C,3,0) -> RRU 본체, 2.6GHz,삼성전자,LTE eNB | E20: 삼성전자
A21: LTE RRU | B21: RRU 850M | C21: 1000067625 | D21: 850MHz ARRU | E21: 삼성전자
A22: LTE RRU | B22: RRU 800M(40W) | C22: 1000049935 | D22: =VLOOKUP(C22,[1]자재마스터!$A:$C,3,0) -> RRU(종단형),40W,삼성전자,LTE eNB | E22: 삼성전자
A23: LTE RRU | B23: RRU 800M(40W) | C23: 1000052324 | D23: RRU(연결형,HSFP),삼성전자,LTE eNB | E23: 삼성전자
A24: LTE RRU | B24: RRU 800M(40W) | C24: 1000052325 | D24: RRU(종단형,HSFP),삼성전자,LTE eNB | E24: 삼성전자
A25: LTE RRU | B25: RRU 800M(30W) | C25: 1000048114 | D25: =VLOOKUP(C25,[1]자재마스터!$A:$C,3,0) -> RRU(종단형),삼성전자,LTE eNB | E25: 삼성전자
A26: LTE RRU | B26: RRU 800M(10W) | C26: 1000053053 | D26: =VLOOKUP(C26,[1]자재마스터!$A:$C,3,0) -> 소형RRU 850MHz,삼성전자,LTE eNB | E26: 삼성전자
A27: LTE RRU | B27: RRU 800M(10W) | C27: 1000053147 | D27: =VLOOKUP(C27,[1]자재마스터!$A:$C,3,0) -> 통합소형RRU,삼성전자,LTE eNB | E27: 삼성전자
A28: LHS | B28: LS-3.5G | C28: 1000064695 | D28: =VLOOKUP(C28,[1]자재마스터!$A:$C,3,0) -> LS-3.5G-100M,삼성전자,5G | E28: 삼성전자
A29: L9TU | B29: L9TU | C29: 1000048112 | D29: =VLOOKUP(C29,[1]자재마스터!$A:$C,3,0) -> L9TU(단거리용),삼성전자,LTE eNB | E29: 삼성전자
A30: L9TU | B30: L9TU | C30: 1000048123 | D30: =VLOOKUP(C30,[1]자재마스터!$A:$C,3,0) -> L9TU(장거리용),삼성전자,LTE eNB | E30: 삼성전자
A31: 5G | B31: RO-GIRO-DS(0120) | C31: 1000065475 | D31: =VLOOKUP(C31,[1]자재마스터!$A:$C,3,0) -> gIRO-DS(0120):RO,(주)씨에스,gIRO-DS(0120):RO | E31: 씨에스
A32: 5G | B32: RO-GIRO-DS(0120) | C32: 1000065468 | D32: =VLOOKUP(C32,[1]자재마스터!$A:$C,3,0) -> gIRO-DS(0120):RO/SKTS,SKTS,gIRO-DS(0120):RO/SKTS | E32: SKTS
A33: 5G | B33: RO-GIRO-DS(01W0) | C33: 1000065890 | D33: =VLOOKUP(C33,[1]자재마스터!$A:$C,3,0) -> gIRO-DS(01W0):RO/SKTS,SKTS,gIRO-DS(01W0):RO/SKTS | E33: SKTS
A34: 5G | B34: RO-GIRO-DS(01W0) | C34: 1000065886 | D34: =VLOOKUP(C34,[1]자재마스터!$A:$C,3,0) -> gIRO-DS(01W0)_IBS:RO/씨에스,(주)씨에스,gIRO-DS(01W0)_IBS:RO/씨에스 | E34: 씨에스
A35: 5G | B35: RO-GIRO-DS(8020) | C35: 1000065472 | D35: =VLOOKUP(C35,[1]자재마스터!$A:$C,3,0) -> gIRO-DS(8020):RO,(주)씨에스,gIRO-DS(8020):RO | E35: 씨에스
A36: 5G | B36: RO-GIRO-DS(80W0) | C36: 1000065884 | D36: =VLOOKUP(C36,[1]자재마스터!$A:$C,3,0) -> gIRO-DS(80W0)_IBS:RO/씨에스,(주)씨에스,gIRO-DS(80W0)_IBS:RO/씨에스 | E36: 씨에스
... A57: LTE | B57: RO-IRO-D(8100) | C57: 1000065739 | D57: =VLOOKUP(C57,[1]자재마스터!$A:$C,3,0) -> IRO-D(8100):RO/SKTS,SKTS,IRO-D(8100):RO/SKTS | E57: SKTS
A58: LTE | B58: RO-IRO-D(8100) | C58: 1000066715 | D58: IRO-D(8100):RO_SFP제외/PCNIENG,팬택씨앤아이엔지니어링,IRO-D(8100):RO_SFP제외/PCNIENG | E58: 팬택
A59: LTE | B59: RO-IRO-D(8100) | C59: 1000066746 | D59: =VLOOKUP(C59,[1]자재마스터!$A:$C,3,0) -> IRO-D(8100):RO_SFP제외/쏠리드,쏠리드,IRO-D(8100):RO_SFP제외/쏠리드 | E59: 쏠리드
A60: LTE | B60: RO-IRO-D(8100) | C60: 1000066744 | D60: =VLOOKUP(C60,[1]자재마스터!$A:$C,3,0) -> IRO-D(8100):RO_SFP제외/씨에스,(주)씨에스,IRO-D(8100):RO_SFP제외/씨에스 | E60: 씨에스
A61: LTE | B61: RO-IRO-T(01W6) | C61: 1000060806 | D61: =VLOOKUP(C61,[1]자재마스터!$A:$C,3,0) -> IRO-T-(01W6):RO/씨에스,(주)씨에스,IRO-T-(01W6):RO/씨에스 | E61: 씨에스
A62: LTE | B62: RO-IRO-T(80W6) | C62: 1000060402 | D62: =VLOOKUP(C62,[1]자재마스터!$A:$C,3,0) -> IRO-T(80W6):RO,쏠리드,IRO-T(80W6):RO | E62: 쏠리드
A63: LTE | B63: RO-IRO-T(8120) | C63: 1000061036 | D63: =VLOOKUP(C63,[1]자재마스터!$A:$C,3,0) -> IRO-T(8120):IMHS,쏠리드,IRO-T(8120):IMHS | E63: 쏠리드
A64: LTE | B64: RO-IRO-T(81W0) | C64: 1000061005 | D64: =VLOOKUP(C64,[1]자재마스터!$A:$C,3,0) -> IRO-T(81W0):RO/SKTS,SKTS,IRO-T(81W0):RO/SKTS | E64: SKTS
A65: LTE | B65: RO-IRO-T(81W0) | C65: 1000061033 | D65: =VLOOKUP(C65,[1]자재마스터!$A:$C,3,0) -> IRO-T(81W0):RO,쏠리드,IRO-T(81W0):RO | E65: 쏠리드
A66: LTE | B66: RO-IRO-T(81W0) | C66: 1000061046 | D66: =VLOOKUP(C66,[1]자재마스터!$A:$C,3,0) -> IRO-T-(81W0):RO/씨에스,(주)씨에스,IRO-T-(81W0):RO/씨에스 | E66: 씨에스
...

Sheet RRU, MiBos, W, 설비물자
A1: 대분류 | B1: 중분류 | C1: 세분류 | D1: 자재코드 | E1: 품명 | F1: 제조업체 | G1: 이월_신품 | H1: 이월_구품 | I1: 이월(재고) | J1: 신품 | K1: 구품 | L1: 재고 | M1: 전체
A2: RRU | B2: DBRRU | C2: 2.1G/1.8G | D2: 1000065286 | E2: =VLOOKUP(D2,[1]자재마스터!$A:$C,3,0) -> Dualband RU(2.1G/1.8G),삼성전자,LTE RAN | F2: 삼성전자
A3: RRU | B3: ERRU | C3: WCDMA | D3: 1000028338 | E3: =VLOOKUP(D3,[1]자재마스터!$A:$C,3,0) -> DC,삼성전자,RRU,WCDMA,ERRU | F3: 삼성전자
A4: RRU | B4: ERRU | C4: WCDMA | D4: 1000028339 | E4: =VLOOKUP(D4,[1]자재마스터!$A:$C,3,0) -> AC,삼성전자,RRU,WCDMA,ERRU | F4: 삼성전자
A5: RRU | B5: RRU | C5: 1.8G(20W) | D5: 1000056038 | E5: =VLOOKUP(D5,[1]자재마스터!$A:$C,3,0) -> CRU 본체,1.8GHz,삼성전자,LTE eNB | F5: 삼성전자
A6: RRU | B6: RRU | C6: 1.8G | D6: 1000051223 | E6: =VLOOKUP(D6,[1]자재마스터!$A:$C,3,0) -> RRU(종단형),1.8GHz,삼성전자,LTE eNB | F6: 삼성전자
A7: RRU | B7: RRU | C7: 1.8G | D7: 1000051224 | E7: =VLOOKUP(D7,[1]자재마스터!$A:$C,3,0) -> RRU(연결형),1.8GHz,삼성전자,LTE eNB | F7: 삼성전자
A8: RRU | B8: RRU | C8: 1.8G | D8: 1000052322 | E8: =VLOOKUP(D8,[1]자재마스터!$A:$C,3,0) -> RRU(연결형,HSFP),1.8GHz,삼성전자,LTE eNB | F8: 삼성전자
A9: RRU | B9: RRU | C9: 1.8G | D9: 1000052323 | E9: =VLOOKUP(D9,[1]자재마스터!$A:$C,3,0) -> RRU(종단형,HSFP),1.8GHz,삼성전자,LTE eNB | F9: 삼성전자
A10: RRU | B10: RRU | C10: 1.8G | D10: 1000052729 | E10: =VLOOKUP(D10,[1]자재마스터!$A:$C,3,0) -> RRU(종단형,HSFP 1350nm),1.8GHz,삼성전자,LTE eNB | F10: 삼성전자
A11: RRU | B11: RRU | C11: 1.8G | D11: 1000056039 | E11: =VLOOKUP(D11,[1]자재마스터!$A:$C,3,0) -> ARRU 본체,1.8GHz,삼성전자,LTE eNB | F11: 삼성전자
A12: RRU | B12: RRU | C12: 2.1G | D12: 1000055333 | E12: =VLOOKUP(D12,[1]자재마스터!$A:$C,3,0) -> ARRU(종단형,HSFP 1,351nm),2.1GHz,삼성전자,LTE eNB | F12: 삼성전자
A13: RRU | B13: RRU | C13: 2.1G | D13: 1000055334 | E13: =VLOOKUP(D13,[1]자재마스터!$A:$C,3,0) -> ARRU 종단형, HSFP, 2.1GHz,삼성전자,LTE eNB | F13: 삼성전자
... A15: RRU | B15: RRU | C15: 2.6G | D15: 1000059604 | E15: =VLOOKUP(D15,[1]자재마스터!$A:$C,3,0) -> RRU 본체, 2.6GHz,삼성전자,LTE eNB | F15: 삼성전자
B16: RRU | C16: 850M | D16: 1000067625 | E16: 850MHz ARRU | F16: 삼성전자
A17: RRU | B17: RRU | C17: 800M(30W) | D17: 1000048114 | E17: =VLOOKUP(D17,[1]자재마스터!$A:$C,3,0) -> RRU(종단형),삼성전자,LTE eNB | F17: 삼성전자
A18: RRU | B18: RRU | C18: 800M(80W) | D18: 1000049910 | E18: =VLOOKUP(D18,[1]자재마스터!$A:$C,3,0) -> RRU(연결형),80W,삼성전자,LTE eNB | F18: 삼성전자
A19: RRU | B19: RRU | C19: 800M(40W) | D19: 1000049935 | E19: =VLOOKUP(D19,[1]자재마스터!$A:$C,3,0) -> RRU(종단형),40W,삼성전자,LTE eNB | F19: 삼성전자
A20: RRU | B20: RRU | C20: 800M(40W) | D20: 1000052324 | E20: =VLOOKUP(D20,[1]자재마스터!$A:$C,3,0) -> RRU(연결형,HSFP),삼성전자,LTE eNB | F20: 삼성전자
A21: RRU | B21: RRU | C21: 800M(40W) | D21: 1000052325 | E21: =VLOOKUP(D21,[1]자재마스터!$A:$C,3,0) -> RRU(종단형,HSFP),삼성전자,LTE eNB | F21: 삼성전자
A22: RRU | B22: RRU | C22: 800M(20W) | D22: 1000053053 | E22: =VLOOKUP(D22,[1]자재마스터!$A:$C,3,0) -> 소형RRU 850MHz,삼성전자,LTE eNB | F22: 삼성전자
A23: RRU | B23: RRU | C23: 800M(10W)/1.8G(20W) | D23: 1000053147 | E23: =VLOOKUP(D23,[1]자재마스터!$A:$C,3,0) -> 통합소형RRU,삼성전자,LTE eNB | F23: 삼성전자
A24: LTE 정류기 | B24: RRU정류기 | C24: 소형 | D24: 1000050851 | E24: =VLOOKUP(D24,[1]자재마스터!$A:$C,3,0) -> LTE RRU용 소형정류기_27V 표준형,LTE RRU용 소형정류기_27V 표준형 | F24: 동아
A25: LTE 정류기 | B25: RRU정류기 | C25: 소형 | D25: 1000050885 | E25: =VLOOKUP(D25,[1]자재마스터!$A:$C,3,0) -> LTE RRU용 소형정류기_27V 표준형(우리),우리시스템즈 | F25: 우리
A26: LTE 정류기 | B26: RRU정류기 | C26: 소형 | D26: 1000052775 | E26: =VLOOKUP(D26,[1]자재마스터!$A:$C,3,0) -> LTE RRU용 소형정류기,27V 표준형(SKTS) | F26: SKTS
A27: LTE 정류기 | B27: RRU정류기 | C27: 소형 | D27: 1000049938 | E27: =VLOOKUP(D27,[1]자재마스터!$A:$C,3,0) -> RRU정류기(소형),40W용,삼성전자,LTE eNB | F27: 삼성전자
A28: LTE 정류기 | B28: RRU정류기 | C28: 소형 | D28: 1000050798 | E28: =VLOOKUP(D28,[1]자재마스터!$A:$C,3,0) -> LTE RRU 비표준형 소형정류기_삼성,LTE RRU 비표준형 소형정류기_삼성 | F28: 삼성전자
A29: LTE 정류기 | B29: RRU정류기 | C29: 소형 | D29: 1000048105 | E29: =VLOOKUP(D29,[1]자재마스터!$A:$C,3,0) -> RRU정류기(소형),삼성전자,LTE eNB | F29: 삼성전자
B30: RRU정류기 | C30: 중형 | D30: 1000049936 | E30: =VLOOKUP(D30,[1]자재마스터!$A:$C,3,0) -> RRU정류기(중형),40W용,삼성전자,LTE eNB | F30: 삼성전자
B31: RRU정류기 | C31: 중형 | D31: 1000049937 | E31: =VLOOKUP(D31,[1]자재마스터!$A:$C,3,0) -> RRU정류모듈(중형),40W용,삼성전자,LTE eNB | F31: 삼성전자
A32: LTE 정류기 | B32: RRU정류기 | C32: 통합형 | D32: 1000054362 | E32: =VLOOKUP(D32,[1]자재마스터!$A:$C,3,0) -> LTE RRU용 통합형 정류기_27V,(SKTS) | F32: SKTS
A33: LTE 정류기 | B33: RRU정류기 | C33: 통합형 | D33: 1000054364 | E33: =VLOOKUP(D33,[1]자재마스터!$A:$C,3,0) -> LTE RRU용 통합형 정류기_27V,(우리) | F33: 우리
A34: LTE 정류기 | B34: RRU정류기 | C34: 통합형 | D34: 1000060480 | E34: =VLOOKUP(D34,[1]자재마스터!$A:$C,3,0) -> LTE통합소형,Compact정류기 2port(27V) | F34: 동아
A35: LTE 정류기 | B35: RRU정류기 | C35: 통합형 | D35: 1000060531 | E35: =VLOOKUP(D35,[1]자재마스터!$A:$C,3,0) -> LTE통합소형,Compact정류기(27V)용 축전지케이스
A36: LTE 정류기 | B36: RRU정류기 | C36: 통합형 | D36: 1000060991 | E36: =VLOOKUP(D36,[1]자재마스터!$A:$C,3,0) -> LTE통합소형,Compact정류기(27V)_케이블통합형 | F36: SKTS, 동아
B37: RRU정류기 | C37: 통합형 | D37: 1000066996 | E37: 소형정류기 LTE통합Compact 27V 개선브라켓 | F37: SKTS, 동아
A38: LTE 정류기 | B38: RRU정류기 | C38: 통합형 | D38: 1000051532 | E38: =VLOOKUP(D38,[1]자재마스터!$A:$C,3,0) -> LTE 인빌딩용 27V 소형 정류기,1.8GHz 통합형 27V | F38: 동아,우리,SKTS
A39: LTE 축전지 | B39: RRU축전지 | C39: 리튬축전지 | D39: 1000065678 | E39: =VLOOKUP(D39,[1]자재마스터!$A:$C,3,0) -> 리튬축전지 함체_컴팩트형 정류기용,,,,
A40: LTE 축전지 | B40: RRU축전지 | C40: 리튬축전지 | D40: 1000065676 | E40: =VLOOKUP(D40,[1]자재마스터!$A:$C,3,0) -> 리튬축전지 팩(24V 10Ah)_8Socket,,,,
A41: LTE 축전지 | B41: RRU축전지 | C41: 리튬축전지 | D41: 1000060532 | E41: =VLOOKUP(D41,[1]자재마스터!$A:$C,3,0) -> 리튬축전지 팩(24V 10Ah)_RRU 컴팩트정류기용,.
...

Sheet 5G, LTE(인빌딩, Legacy)
A1: 구분 | B1: 구분1 | C1: 자재코드 | D1: 품명 | E1: 제조사 | F1: 이월_신품 | G1: 이월_구품 | H1: 이월(재고) | I1: 신품 | J1: 구품 | K1: 재고 | L1: 전체
A2: AAU(인) | B2: AAU-3.5G(W) | C2: 1000064730 | D2: =VLOOKUP(C2,[1]자재마스터!$A:$C,3,0) -> AAU-3.5G-4T(W)/ANTS,에이앤티에스,AAU-3.5G-4T(W)/ANTS | E2: ANTS
A3: AAU(인) | B3: AAU-3.5G(W) | C3: 1000064880 | D3: =VLOOKUP(C3,[1]자재마스터!$A:$C,3,0) -> AAU-3.5G-4T(W)/SKTS,SKTS,AAU-3.5G-4T(W)/SKTS | E3: SKTS
A4: AAU(인) | B4: AAU-3.5G(C) | C4: 1000064781 | D4: =VLOOKUP(C4,[1]자재마스터!$A:$C,3,0) -> AAU-3.5G-4T(C)/ANTS,에이앤티에스,AAU-3.5G-4T(C)/ANTS | E4: ANTS
A5: AAU(인) | B5: AAU-3.5G(C) | C5: 1000064941 | D5: =VLOOKUP(C5,[1]자재마스터!$A:$C,3,0) -> AAU-3.5G-4T(C)/SKTS,SKTS,AAU-3.5G-4T(C)/SKTS | E5: SKTS
A6: AAU(인) 전원 | B6: Adaptor 대 | C6: 1000064782 | D6: =VLOOKUP(C6,[1]자재마스터!$A:$C,3,0) -> AAU용 전원 Adaptor/ANTS,에이앤티에스,AAU용 전원 Adaptor/ANTS | E6: ANTS
A7: AAU(인) 전원 | B7: Adaptor 대 | C7: 1000064942 | D7: =VLOOKUP(C7,[1]자재마스터!$A:$C,3,0) -> AAU용 전원 Adaptor/SKTS,SKTS,AAU용 전원 Adaptor/SKTS | E7: SKTS
A8: AAU(인) 전원 | B8: Adaptor 소 | C8: 1000064968 | D8: =VLOOKUP(C8,[1]자재마스터!$A:$C,3,0) -> AAU용 전원 Adaptor(소용량)/ANTS,에이앤티에스,AAU용 전원 Adaptor(소용량)/ANTS | E8: ANTS
A9: AAU(인) 전원 | B9: Adaptor 소 | C9: 1000064971 | D9: =VLOOKUP(C9,[1]자재마스터!$A:$C,3,0) -> AAU용 전원 Adaptor(소용량)/SKTS,SKTS,AAU용 전원 Adaptor(소용량)/SKTS | E9: SKTS
A10: AAU(인) 전원 | B10: Adaptor 대 | C10: 1000064947 | D10: =VLOOKUP(C10,[1]자재마스터!$A:$C,3,0) -> AAU용 전원 Adaptor/HFR,HFR,AAU용 전원 Adaptor/HFR | E10: HFR
A11: gIRO(5G) | B11: RO-GIRO-DS(0120) | C11: 1000065475 | D11: =VLOOKUP(C11,[1]자재마스터!$A:$C,3,0) -> gIRO-DS(0120):RO,(주)씨에스,gIRO-DS(0120):RO | E11: 씨에스
A12: gIRO(5G) | B12: RO-GIRO-DS(0120) | C12: 1000065468 | D12: =VLOOKUP(C12,[1]자재마스터!$A:$C,3,0) -> gIRO-DS(0120):RO/SKTS,SKTS,gIRO-DS(0120):RO/SKTS | E12: SKTS
A13: gIRO(5G) | B13: RO-GIRO-DS(01W0) | C13: 1000065890 | D13: =VLOOKUP(C13,[1]자재마스터!$A:$C,3,0) -> gIRO-DS(01W0):RO/SKTS,SKTS,gIRO-DS(01W0):RO/SKTS | E13: SKTS
... A24: gIRO(5G) | B24: RO-GIRO-T(8120) | C24: 1000065734 | D24: =VLOOKUP(C24,[1]자재마스터!$A:$C,3,0) -> gIRO-T(8120):RO/씨에스,(주)씨에스,gIRO-T(8120):RO | E24: 씨에스
B25: RO-GIRO-T(81W0) | C25: 1000066100 | D25: gIRO-T(81W0):RO/씨에스 | E25: 씨에스
A26: LHS | B26: LS-3.5G | C26: 1000064695 | D26: =VLOOKUP(C26,[1]자재마스터!$A:$C,3,0) -> LS-3.5G-100M,삼성전자,5G | E26: 삼성
A27: LHS | B27: LSH 정류기 | C27: 1000064696 | D27: =VLOOKUP(C27,[1]자재마스터!$A:$C,3,0) -> Compact정류기,Layer Splitter용 정류시스템 48V_600W | E27: 삼성
A28: L9TU | B28: L9TU | C28: 1000048112 | D28: =VLOOKUP(C28,[1]자재마스터!$A:$C,3,0) -> L9TU(단거리용),삼성전자,LTE eNB | E28: 삼성
A29: L9TU | B29: L9TU | C29: 1000056093 | D29: =VLOOKUP(C29,[1]자재마스터!$A:$C,3,0) -> L9TU 전원케이블,삼성전자,LTE eNB | E29: 삼성
A30: L9TU | B30: L9TU | C30: 1000048123 | D30: =VLOOKUP(C30,[1]자재마스터!$A:$C,3,0) -> L9TU(장거리용),삼성전자,LTE eNB | E30: 삼성
A31: 800M AMP | B31: IRO-800 AMP | C31: 1000062219 | E31: 쏠리드
A32: 800M AMP | B32: IRO-800 AMP | C32: 1000062287 | D32: =VLOOKUP(C32,[1]자재마스터!$A:$C,3,0) -> IRO:IRO_800M Amp/SKTS,SKTS,IRO:IRO_800M Amp/SKTS | E32: SKTS
A33: 800M AMP | B33: IRO-800 AMP | C33: 1000062417 | D33: =VLOOKUP(C33,[1]자재마스터!$A:$C,3,0) -> IRO,LTE800M모듈,(주)씨에스,IRO,LTE800M모듈 | E33: 씨에스
A34: 1.8G AMP | B34: IRO-1.8 AMP | C34: 1000062212 | D34: =VLOOKUP(C34,[1]자재마스터!$A:$C,3,0) -> IRO 1.8G AMP,쏠리드,IRO 1.8G AMP | E34: 쏠리드
A35: 2.1G AMP | B35: IRO-2.1 AMP | C35: 1000061406 | D35: =VLOOKUP(C35,[1]자재마스터!$A:$C,3,0) -> IRO 2.1G RFU,쏠리드,IRO 2.1G RFU | E35: 쏠리드
A36: 2.1G AMP | B36: IRO-2.1 AMP | C36: 1000061447 | D36: =VLOOKUP(C36,[1]자재마스터!$A:$C,3,0) -> IRO:IRO_2.1G Amp/SKTS,SKTS,IRO:IRO_2.1G Amp/SKTS | E36: SKTS
A37: 2.1G AMP | B37: IRO-2.1 AMP | C37: 1000061413 | D37: =VLOOKUP(C37,[1]자재마스터!$A:$C,3,0) -> IRO,LTE2.1G모듈,(주)씨에스,IRO,LTE2.1G모듈 | E37: 씨에스
A38: 2.6G AMP | B38: IRO-2.6 AMP | C38: 1000061461 | D38: =VLOOKUP(C38,[1]자재마스터!$A:$C,3,0) -> IRO:IRO_2.6G Amp/SKTS,SKTS,IRO:IRO_2.6G Amp/SKTS | E38: SKTS
A39: 2.6G AMP | B39: IRO-2.6 AMP | C39: 1000061414 | D39: =VLOOKUP(C39,[1]자재마스터!$A:$C,3,0) -> IRO,LTE2.6G모듈,(주)씨에스,IRO,LTE2.6G모듈 | E39: 씨에스
A40: 2.6G AMP | B40: IRO-2.6 AMP | C40: 1000061434 | D40: =VLOOKUP(C40,[1]자재마스터!$A:$C,3,0) -> IRO-2.6G LTE-AMP,암니스,IRO-2.6G LTE-AMP | E40: 암니스
A41: 2.6G AMP | B41: IRO-2.6 AMP | C41: 1000061407 | D41: =VLOOKUP(C41,[1]자재마스터!$A:$C,3,0) -> IRO 2.6G RFU,쏠리드,IRO 2.6G RFU | E41: 쏠리드
A42: IRO-M | B42: RO-IRO-S(0100) | C42: 1000065327 | D42: =VLOOKUP(C42,[1]자재마스터!$A:$C,3,0) -> IRO-S(0100):RO,(주)씨에스,IRO-S(0100):RO | E42: 씨에스
A43: IRO-M | B43: RO-IRO-S(0100) | C43: 1000065325 | D43: =VLOOKUP(C43,[1]자재마스터!$A:$C,3,0) -> IRO-S(0100):RO,쏠리드,IRO-S(0100):RO | E43: 쏠리드
... A97: SMHS | B97: SMHS_PSU | C97: 1000062134 | D97: =VLOOKUP(C97,[1]자재마스터!$A:$C,3,0) -> SMHS-PSU Unit ,쏠리드,PSU Unit | E97: 쏠리드
A98: LORA | B98: LoRa 안테나 | C98: 1000059290 | D98: =VLOOKUP(C98,[1]자재마스터!$A:$C,3,0) -> 기지국용 안테나,0.9-LoRa OmPole-3-360/60-T0(LoRa)
A99: LORA | B99: LoRa Gateway | C99: 1000059480 | D99: =VLOOKUP(C99,[1]자재마스터!$A:$C,3,0) -> IOT 기지국(LoRa Gateway),SK텔레시스,SIG-LO090 | E99: SKTS
A100: LORA | B100: LoRa Indoor | C100: 1000060993 | D100: =VLOOKUP(C100,[1]자재마스터!$A:$C,3,0) -> LoRa 900M Indoor 기지국,콘텔라,저전력 IoT 기지국 | E100: 콘텔라
A101: LORA | B101: LoRa Gateway | C101: 1000059441 | D101: =VLOOKUP(C101,[1]자재마스터!$A:$C,3,0) -> LoRa 900M Gateway,콘텔라,저전력 IoT 기지국 | E101: 콘텔라
A102: LORA | B102: LoRa Revision | C102: 1000064603 | D102: =VLOOKUP(C102,[1]자재마스터!$A:$C,3,0) -> LoRa 900M Indoor 기지국(Revision),콘텔라,저전력 IoT 기지국 | E102: 콘텔라
A103: LORA | B103: LoRa Gateway | C103: 1000059451 | D103: =VLOOKUP(C103,[1]자재마스터!$A:$C,3,0) -> LoRa IoT 기지국,삼성전자,LoRa | E103: 삼성
...

Sheet QMHS, IMHS, AMHS
A1: 구분 | B1: 자재코드 | C1: 품명 | D1: 제조사 | E1: 이월_신품 | F1: 이월_구품 | G1: 이월(재고) | H1: 신품 | I1: 구품 | J1: 재고 | K1: 전체
A2: QMHS | B2: 1000052089 | C2: MiBOS-T-L0_IBS:MHS/쏠리드,쏠리드,MiBOS-T-L0_IBS:MHS/쏠리드 | D2: 쏠리드
A3: QMHS | B3: 1000052094 | C3: MiBOS-T-L60_IBS:MHS/쏠리드,쏠리드,MiBOS-T-L60_IBS:MHS/쏠리드 | D3: 쏠리드
A4: QMHS | B4: 1000052112 | C4: MiBOS-D-L60:MHS/쏠리드,쏠리드,MiBOS-D-L60:MHS/쏠리드 | D4: 쏠리드
A5: QMHS | B5: 1000052117 | C5: MiBOS-T-L0:MHS/쏠리드,쏠리드,MiBOS-T-L0:MHS/쏠리드 | D5: 쏠리드
A6: QMHS | B6: 1000052122 | C6: MiBOS-T-L60:MHS/쏠리드,쏠리드,MiBOS-T-L60:MHS/쏠리드 | D6: 쏠리드
A7: QMHS | B7: 1000052127 | C7: MiBOS-Q-L60:MHS/쏠리드,쏠리드,MiBOS-Q-L60:MHS/쏠리드 | D7: 쏠리드
A8: QMHS | B8: 1000052173 | C8: MiBOS-T-L0_IBS:MHS/GSI,GSI,MiBOS-T-L0_IBS:MHS/GSI | D8: GSI
A9: QMHS | B9: 1000052178 | C9: MiBOS-T-L60_IBS:MHS/GSI,GSI,MiBOS-T-L60_IBS:MHS/GSI | D9: GSI
A10: QMHS | B10: 1000052201 | C10: MiBOS-T-L0:MHS/GSI,GSI,MiBOS-T-L0:MHS/GSI | D10: GSI
A11: QMHS | B11: 1000052206 | C11: MiBOS-T-L60:MHS/GSI,GSI,MiBOS-T-L60:MHS/GSI | D11: GSI
A12: QMHS | B12: 1000052211 | C12: MiBOS-Q-L60:MHS/GSI,GSI,MiBOS-Q-L60:MHS/GSI | D12: GSI
A13: QMHS | B13: 1000052257 | C13: MiBOS-T-L0_IBS:MHS/SKTS,SKTS,MiBOS-T-L0_IBS:MHS/SKTS | D13: SKTS
... A72: AMHS | B72: 1000063105 | C72: MiBOS-AD-L60:RO(가로)쏠리드MiBOS-AD-L | D72: (주)쏠리드

Sheet SFP, MUX, OCM
A1: 대분류 | B1: 중분류 | C1: 자재코드 | D1: 자재명 | E1: 이월_신품 | F1: 이월_구품 | G1: 이월(재고) | H1: 신품 | I1: 구품 | J1: 재고 | K1: 전체
A2: Bypass | B2: SMUX-Bypass | C2: 1000064457 | D2: SMUX-Bypass,5G-PON
A3: S-MUX | B3: SMUX-C | C3: 1000064447 | D3: SMUX-C_New,SMUX COT 1290nm(필터형)
A4: S-MUX | B4: SMUX-R | C4: 1000064448 | D4: SMUX-R_New,SMUX RN 1290nm(필터형)
A5: S-MUX | B5: SMUX EN | C5: 1000065374 | D5: SMUX EN,썬웨이브텍,1290nm
A6: C-MUX | B6: C-MUX 셀프 | C6: 1000063357 | D6: 5G PON SMUX_SMDS,썬웨이브텍,Passive Shelf - 1U / 4Slot MUX Shelf
A7: C-MUX | B7: C-MUX 기본형_C | C7: 1000065560 | D7: CMUX-C,썬웨이브텍,CMUX COT 1290nm_Ch1-4
A8: C-MUX | B8: C-MUX 기본형_R | C8: 1000065582 | D8: CMUX-R,썬웨이브텍,CMUX RN 1290nm_Ch1-4
A9: C-MUX | B9: C-MUX 확장형_C | C9: 1000065581 | D9: CMUX-C(확장),썬웨이브텍,CMUX COT 1290nm_Ch5-8
A10: C-MUX | B10: C-MUX 확장형_R | C10: 1000065583 | D10: CMUX-R(확장),썬웨이브텍,CMUX RN 1290nm_Ch5-8
A11: C-MUX | B11: CMUX-Ring모듈 | C11: 1000065399 | D11: CMUX-Ring모듈,썬웨이브텍,Ring용 모듈
A12: C-MUX | B12: C-MUX 셀프 | C12: 1000063353 | D12: IPS-1U_MUX,쏠리드,5G-PON
A13: C-MUX | B13: C-MUX 기본형_C | C13: 1000065364 | D13: C-MUX CO1,쏠리드,5G-PON
... A338: SFP | B338: 강원 LTE 용 | C338: 1000065885 | D338: HSFP 1590nm 3G DUL,NSN,HSFP 1590nm 3G DUL

Sheet 부대물자
A1: 분류 | B1: 자재코드 | C1: 품명 | D1: 이월_신품 | E1: 이월_구품 | F1: 이월(재고) | G1: 신품 | H1: 구품 | I1: 재고 | J1: 전체
A2: 분배기 | B2: 1000063350 | C2: 5G 분배기,5G단독 2MD-500W U 1:1
A3: 분배기 | B3: 1000063349 | C3: 5G 분배기,5G단독 3MD-500W T 1:1:1
A4: 분배기 | B4: 1000063348 | C4: 5G 분배기,5G단독 2MD-500W T 1:1
A5: 분배기 | B5: 1000063340 | C5: 5G 분배기,(인빌딩) 5G 2N-150W(1:1)
A6: 분배기 | B6: 1000063339 | C6: 5G 분배기,5G단독 3MD-500W F 1:1:1
A7: 분배기 | B7: 1000063338 | C7: 5G 분배기,5G단독 3MD-500W U 1:1:1
A8: 분배기 | B8: 1000062904 | C8: 기지국분배기,3Way분배기_DIN_균등(111)_F
A9: 분배기 | B9: 1000040964 | C9: 기지국분배기 : BBPD-2DIN-300-U
A10: 분배기 | B10: 1000040963 | C10: 기지국분배기 : BBPD-2DIN-73-300-U
A11: 분배기 | B11: 1000040962 | C11: 기지국분배기 : BBPD-3DIN-300-U
A12: 분배기 | B12: 1000040961 | C12: 기지국분배기 : BBPD-3DIN-211-300-U
A13: 분배기 | B13: 1000040950 | C13: 기지국분배기 : BBPD-4DIN-300-U
... A84: 분배기 | B84: 1000063391 | C84: 5G 분배기,(인빌딩) 5G 2N-150W(7:3)

Sheet 안테나
A1: 자재코드 | B1: 품명 | C1: 이월_신품 | D1: 이월_구품 | E1: 이월(재고) | F1: 신품 | G1: 구품 | H1: 재고 | I1: 전체
A2: 1000026275 | B2: 기지국용안테나,2G-3G,C/W/VP-13/16-65/60-15/7-T0-DIPLEXER
A3: 1000037799 | B3: C/W/Wi/VP-5/9-125/70-60/30-T0-Cir-1Port,기지국안테나
A4: 1000048423 | B4: 중계기용안테나,GPS-TNC,GPS ANT
A5: 1000051270 | B5: 기지국안테나,L/L-A/W/XP-14/15-65/63-15/10-TA-15/10
A6: 1000051312 | B6: 기지국안테나,L/L-A/W/XP-12/14-65/63-20/13-TA-15/10
A7: 1000051542 | B7: 기지국용안테나,L-A/W/XP-17-65/7-T0
A8: 1000051545 | B8: 기지국용안테나,L-A/W/XP-15-65/13-T0
A9: 1000051546 | B9: 기지국용안테나,L-A/W/XP-17-65/7-TA-10
A10: 1000051547 | B10: 기지국용안테나,L-A/W/XP-15-65/13-TA-15
A11: 1000052740 | B11: 기지국안테나,L-A/W/XP-19-33/7-T0
A12: 1000052743 | B12: L/L-A/W/XP-5/8-100/65-75/60-T0-Circle-2Port-Diplexer
A13: 1000053152 | B13: 기지국안테나,MULTI-VENDOR,L/L-A/W/XP-12/14-65/63-20/13-TA-15/10-Diplexer
... A95: 1000066615 | B95: 0.8/1.8/2.1/2.6/3.5/Omni-2/2/3/3-360-40/20/20/10-Flat
